[2022-07-19 09:27:09,776] {taskinstance.py:1159} INFO - Dependencies all met for <TaskInstance: simple_dag.respond scheduled__2022-07-19T09:26:00+00:00 [queued]>
[2022-07-19 09:27:09,785] {taskinstance.py:1159} INFO - Dependencies all met for <TaskInstance: simple_dag.respond scheduled__2022-07-19T09:26:00+00:00 [queued]>
[2022-07-19 09:27:09,785] {taskinstance.py:1356} INFO - 
--------------------------------------------------------------------------------
[2022-07-19 09:27:09,786] {taskinstance.py:1357} INFO - Starting attempt 1 of 1
[2022-07-19 09:27:09,786] {taskinstance.py:1358} INFO - 
--------------------------------------------------------------------------------
[2022-07-19 09:27:09,803] {taskinstance.py:1377} INFO - Executing <Task(PythonOperator): respond> on 2022-07-19 09:26:00+00:00
[2022-07-19 09:27:09,814] {standard_task_runner.py:52} INFO - Started process 4454 to run task
[2022-07-19 09:27:09,820] {standard_task_runner.py:79} INFO - Running: ['***', 'tasks', 'run', 'simple_dag', 'respond', 'scheduled__2022-07-19T09:26:00+00:00', '--job-id', '208', '--raw', '--subdir', 'DAGS_FOLDER/first_dag.py', '--cfg-path', '/tmp/tmp3646ca4v', '--error-file', '/tmp/tmputzivqkb']
[2022-07-19 09:27:09,822] {standard_task_runner.py:80} INFO - Job 208: Subtask respond
[2022-07-19 09:27:09,905] {task_command.py:370} INFO - Running <TaskInstance: simple_dag.respond scheduled__2022-07-19T09:26:00+00:00 [running]> on host 02ffb48252da
[2022-07-19 09:27:10,003] {taskinstance.py:1571} INFO - Exporting the following env vars:
AIRFLOW_CTX_DAG_OWNER=***
AIRFLOW_CTX_DAG_ID=simple_dag
AIRFLOW_CTX_TASK_ID=respond
AIRFLOW_CTX_EXECUTION_DATE=2022-07-19T09:26:00+00:00
AIRFLOW_CTX_TRY_NUMBER=1
AIRFLOW_CTX_DAG_RUN_ID=scheduled__2022-07-19T09:26:00+00:00
[2022-07-19 09:27:10,006] {taskinstance.py:1889} ERROR - Task failed with exception
Traceback (most recent call last):
  File "/home/airflow/.local/lib/python3.7/site-packages/airflow/operators/python.py", line 171, in execute
    return_value = self.execute_callable()
  File "/home/airflow/.local/lib/python3.7/site-packages/airflow/operators/python.py", line 189, in execute_callable
    return self.python_callable(*self.op_args, **self.op_kwargs)
  File "/opt/airflow/dags/first_dag.py", line 21, in respond
    df = pd.read_csv("../data/20181101_d7_1000_1030.csv", delimiter=";")
  File "/home/airflow/.local/lib/python3.7/site-packages/pandas/util/_decorators.py", line 311, in wrapper
    return func(*args, **kwargs)
  File "/home/airflow/.local/lib/python3.7/site-packages/pandas/io/parsers/readers.py", line 586, in read_csv
    return _read(filepath_or_buffer, kwds)
  File "/home/airflow/.local/lib/python3.7/site-packages/pandas/io/parsers/readers.py", line 482, in _read
    parser = TextFileReader(filepath_or_buffer, **kwds)
  File "/home/airflow/.local/lib/python3.7/site-packages/pandas/io/parsers/readers.py", line 811, in __init__
    self._engine = self._make_engine(self.engine)
  File "/home/airflow/.local/lib/python3.7/site-packages/pandas/io/parsers/readers.py", line 1040, in _make_engine
    return mapping[engine](self.f, **self.options)  # type: ignore[call-arg]
  File "/home/airflow/.local/lib/python3.7/site-packages/pandas/io/parsers/c_parser_wrapper.py", line 51, in __init__
    self._open_handles(src, kwds)
  File "/home/airflow/.local/lib/python3.7/site-packages/pandas/io/parsers/base_parser.py", line 229, in _open_handles
    errors=kwds.get("encoding_errors", "strict"),
  File "/home/airflow/.local/lib/python3.7/site-packages/pandas/io/common.py", line 707, in get_handle
    newline="",
FileNotFoundError: [Errno 2] No such file or directory: '../data/20181101_d7_1000_1030.csv'
[2022-07-19 09:27:10,022] {taskinstance.py:1400} INFO - Marking task as FAILED. dag_id=simple_dag, task_id=respond, execution_date=20220719T092600, start_date=20220719T092709, end_date=20220719T092710
[2022-07-19 09:27:10,035] {standard_task_runner.py:97} ERROR - Failed to execute job 208 for task respond ([Errno 2] No such file or directory: '../data/20181101_d7_1000_1030.csv'; 4454)
[2022-07-19 09:27:10,075] {local_task_job.py:156} INFO - Task exited with return code 1
[2022-07-19 09:27:10,139] {local_task_job.py:273} INFO - 0 downstream tasks scheduled from follow-on schedule check
