[2022-07-19 08:32:02,580] {taskinstance.py:1159} INFO - Dependencies all met for <TaskInstance: simple_dag.greet manual__2022-07-19T08:32:01.391915+00:00 [queued]>
[2022-07-19 08:32:02,594] {taskinstance.py:1159} INFO - Dependencies all met for <TaskInstance: simple_dag.greet manual__2022-07-19T08:32:01.391915+00:00 [queued]>
[2022-07-19 08:32:02,595] {taskinstance.py:1356} INFO - 
--------------------------------------------------------------------------------
[2022-07-19 08:32:02,596] {taskinstance.py:1357} INFO - Starting attempt 1 of 1
[2022-07-19 08:32:02,596] {taskinstance.py:1358} INFO - 
--------------------------------------------------------------------------------
[2022-07-19 08:32:02,629] {taskinstance.py:1377} INFO - Executing <Task(PythonOperator): greet> on 2022-07-19 08:32:01.391915+00:00
[2022-07-19 08:32:02,636] {standard_task_runner.py:52} INFO - Started process 1389 to run task
[2022-07-19 08:32:02,641] {standard_task_runner.py:79} INFO - Running: ['***', 'tasks', 'run', 'simple_dag', 'greet', 'manual__2022-07-19T08:32:01.391915+00:00', '--job-id', '40', '--raw', '--subdir', 'DAGS_FOLDER/first_dag.py', '--cfg-path', '/tmp/tmpuheevrss', '--error-file', '/tmp/tmpejsebsaq']
[2022-07-19 08:32:02,642] {standard_task_runner.py:80} INFO - Job 40: Subtask greet
[2022-07-19 08:32:02,723] {task_command.py:370} INFO - Running <TaskInstance: simple_dag.greet manual__2022-07-19T08:32:01.391915+00:00 [running]> on host 02ffb48252da
[2022-07-19 08:32:02,900] {taskinstance.py:1571} INFO - Exporting the following env vars:
AIRFLOW_CTX_DAG_OWNER=***
AIRFLOW_CTX_DAG_ID=simple_dag
AIRFLOW_CTX_TASK_ID=greet
AIRFLOW_CTX_EXECUTION_DATE=2022-07-19T08:32:01.391915+00:00
AIRFLOW_CTX_TRY_NUMBER=1
AIRFLOW_CTX_DAG_RUN_ID=manual__2022-07-19T08:32:01.391915+00:00
[2022-07-19 08:32:02,906] {logging_mixin.py:115} INFO - Writing in file
[2022-07-19 08:32:02,907] {taskinstance.py:1889} ERROR - Task failed with exception
Traceback (most recent call last):
  File "/home/airflow/.local/lib/python3.7/site-packages/airflow/operators/python.py", line 171, in execute
    return_value = self.execute_callable()
  File "/home/airflow/.local/lib/python3.7/site-packages/airflow/operators/python.py", line 189, in execute_callable
    return self.python_callable(*self.op_args, **self.op_kwargs)
  File "/opt/airflow/dags/first_dag.py", line 12, in greet
    with open(Path().cwd(), "a+", encoding="utf8") as f:
IsADirectoryError: [Errno 21] Is a directory: '/opt/airflow'
[2022-07-19 08:32:02,933] {taskinstance.py:1400} INFO - Marking task as FAILED. dag_id=simple_dag, task_id=greet, execution_date=20220719T083201, start_date=20220719T083202, end_date=20220719T083202
[2022-07-19 08:32:02,963] {standard_task_runner.py:97} ERROR - Failed to execute job 40 for task greet ([Errno 21] Is a directory: '/opt/airflow'; 1389)
[2022-07-19 08:32:03,015] {local_task_job.py:156} INFO - Task exited with return code 1
[2022-07-19 08:32:03,066] {local_task_job.py:273} INFO - 0 downstream tasks scheduled from follow-on schedule check
