[2022-07-19 21:54:06,337] {taskinstance.py:1159} INFO - Dependencies all met for <TaskInstance: simple_dag.load_data scheduled__2022-07-19T21:53:00+00:00 [queued]>
[2022-07-19 21:54:06,351] {taskinstance.py:1159} INFO - Dependencies all met for <TaskInstance: simple_dag.load_data scheduled__2022-07-19T21:53:00+00:00 [queued]>
[2022-07-19 21:54:06,351] {taskinstance.py:1356} INFO - 
--------------------------------------------------------------------------------
[2022-07-19 21:54:06,352] {taskinstance.py:1357} INFO - Starting attempt 1 of 1
[2022-07-19 21:54:06,353] {taskinstance.py:1358} INFO - 
--------------------------------------------------------------------------------
[2022-07-19 21:54:06,377] {taskinstance.py:1377} INFO - Executing <Task(PythonOperator): load_data> on 2022-07-19 21:53:00+00:00
[2022-07-19 21:54:06,382] {standard_task_runner.py:52} INFO - Started process 430 to run task
[2022-07-19 21:54:06,386] {standard_task_runner.py:79} INFO - Running: ['***', 'tasks', 'run', 'simple_dag', 'load_data', 'scheduled__2022-07-19T21:53:00+00:00', '--job-id', '991', '--raw', '--subdir', 'DAGS_FOLDER/first_dag.py', '--cfg-path', '/tmp/tmpfpq249wz', '--error-file', '/tmp/tmpig34h2bp']
[2022-07-19 21:54:06,387] {standard_task_runner.py:80} INFO - Job 991: Subtask load_data
[2022-07-19 21:54:06,486] {task_command.py:370} INFO - Running <TaskInstance: simple_dag.load_data scheduled__2022-07-19T21:53:00+00:00 [running]> on host 29459987bc56
[2022-07-19 21:54:06,620] {taskinstance.py:1571} INFO - Exporting the following env vars:
AIRFLOW_CTX_DAG_OWNER=***
AIRFLOW_CTX_DAG_ID=simple_dag
AIRFLOW_CTX_TASK_ID=load_data
AIRFLOW_CTX_EXECUTION_DATE=2022-07-19T21:53:00+00:00
AIRFLOW_CTX_TRY_NUMBER=1
AIRFLOW_CTX_DAG_RUN_ID=scheduled__2022-07-19T21:53:00+00:00
[2022-07-19 21:54:06,633] {base.py:68} INFO - Using connection ID 'postgres_localhost' for task execution.
[2022-07-19 21:54:06,682] {logging_mixin.py:115} WARNING - /home/***/.local/lib/python3.7/site-packages/pandas/core/generic.py:2882 UserWarning: The spaces in these column names will not be changed. In pandas versions < 0.14, spaces were converted to underscores.
[2022-07-19 21:54:06,691] {taskinstance.py:1889} ERROR - Task failed with exception
Traceback (most recent call last):
  File "/home/airflow/.local/lib/python3.7/site-packages/pandas/io/sql.py", line 2056, in execute
    cur.execute(*args, **kwargs)
psycopg2.errors.UndefinedTable: relation "sqlite_master" does not exist
LINE 1: SELECT name FROM sqlite_master WHERE type='table' AND name=?...
                         ^


The above exception was the direct cause of the following exception:

Traceback (most recent call last):
  File "/home/airflow/.local/lib/python3.7/site-packages/airflow/operators/python.py", line 171, in execute
    return_value = self.execute_callable()
  File "/home/airflow/.local/lib/python3.7/site-packages/airflow/operators/python.py", line 189, in execute_callable
    return self.python_callable(*self.op_args, **self.op_kwargs)
  File "/opt/airflow/dags/first_dag.py", line 25, in insert_data
    index=False,
  File "/home/airflow/.local/lib/python3.7/site-packages/pandas/core/generic.py", line 2882, in to_sql
    method=method,
  File "/home/airflow/.local/lib/python3.7/site-packages/pandas/io/sql.py", line 728, in to_sql
    **engine_kwargs,
  File "/home/airflow/.local/lib/python3.7/site-packages/pandas/io/sql.py", line 2225, in to_sql
    table.create()
  File "/home/airflow/.local/lib/python3.7/site-packages/pandas/io/sql.py", line 856, in create
    if self.exists():
  File "/home/airflow/.local/lib/python3.7/site-packages/pandas/io/sql.py", line 840, in exists
    return self.pd_sql.has_table(self.name, self.schema)
  File "/home/airflow/.local/lib/python3.7/site-packages/pandas/io/sql.py", line 2236, in has_table
    return len(self.execute(query, [name]).fetchall()) > 0
  File "/home/airflow/.local/lib/python3.7/site-packages/pandas/io/sql.py", line 2068, in execute
    raise ex from exc
pandas.io.sql.DatabaseError: Execution failed on sql 'SELECT name FROM sqlite_master WHERE type='table' AND name=?;': relation "sqlite_master" does not exist
LINE 1: SELECT name FROM sqlite_master WHERE type='table' AND name=?...
                         ^

[2022-07-19 21:54:06,712] {taskinstance.py:1400} INFO - Marking task as FAILED. dag_id=simple_dag, task_id=load_data, execution_date=20220719T215300, start_date=20220719T215406, end_date=20220719T215406
[2022-07-19 21:54:06,732] {standard_task_runner.py:97} ERROR - Failed to execute job 991 for task load_data (Execution failed on sql 'SELECT name FROM sqlite_master WHERE type='table' AND name=?;': relation "sqlite_master" does not exist
LINE 1: SELECT name FROM sqlite_master WHERE type='table' AND name=?...
                         ^
; 430)
[2022-07-19 21:54:06,759] {local_task_job.py:156} INFO - Task exited with return code 1
[2022-07-19 21:54:06,808] {local_task_job.py:273} INFO - 0 downstream tasks scheduled from follow-on schedule check
