[2022-07-19 09:29:35,064] {taskinstance.py:1159} INFO - Dependencies all met for <TaskInstance: simple_dag.respond manual__2022-07-19T09:29:25.309362+00:00 [queued]>
[2022-07-19 09:29:35,074] {taskinstance.py:1159} INFO - Dependencies all met for <TaskInstance: simple_dag.respond manual__2022-07-19T09:29:25.309362+00:00 [queued]>
[2022-07-19 09:29:35,075] {taskinstance.py:1356} INFO - 
--------------------------------------------------------------------------------
[2022-07-19 09:29:35,076] {taskinstance.py:1357} INFO - Starting attempt 1 of 1
[2022-07-19 09:29:35,077] {taskinstance.py:1358} INFO - 
--------------------------------------------------------------------------------
[2022-07-19 09:29:35,100] {taskinstance.py:1377} INFO - Executing <Task(PythonOperator): respond> on 2022-07-19 09:29:25.309362+00:00
[2022-07-19 09:29:35,105] {standard_task_runner.py:52} INFO - Started process 4600 to run task
[2022-07-19 09:29:35,109] {standard_task_runner.py:79} INFO - Running: ['***', 'tasks', 'run', 'simple_dag', 'respond', 'manual__2022-07-19T09:29:25.309362+00:00', '--job-id', '217', '--raw', '--subdir', 'DAGS_FOLDER/first_dag.py', '--cfg-path', '/tmp/tmp9aklsj2n', '--error-file', '/tmp/tmpp0fj_d3w']
[2022-07-19 09:29:35,110] {standard_task_runner.py:80} INFO - Job 217: Subtask respond
[2022-07-19 09:29:35,169] {task_command.py:370} INFO - Running <TaskInstance: simple_dag.respond manual__2022-07-19T09:29:25.309362+00:00 [running]> on host 02ffb48252da
[2022-07-19 09:29:35,250] {taskinstance.py:1571} INFO - Exporting the following env vars:
AIRFLOW_CTX_DAG_OWNER=***
AIRFLOW_CTX_DAG_ID=simple_dag
AIRFLOW_CTX_TASK_ID=respond
AIRFLOW_CTX_EXECUTION_DATE=2022-07-19T09:29:25.309362+00:00
AIRFLOW_CTX_TRY_NUMBER=1
AIRFLOW_CTX_DAG_RUN_ID=manual__2022-07-19T09:29:25.309362+00:00
[2022-07-19 09:29:35,252] {taskinstance.py:1889} ERROR - Task failed with exception
Traceback (most recent call last):
  File "/home/airflow/.local/lib/python3.7/site-packages/airflow/operators/python.py", line 171, in execute
    return_value = self.execute_callable()
  File "/home/airflow/.local/lib/python3.7/site-packages/airflow/operators/python.py", line 189, in execute_callable
    return self.python_callable(*self.op_args, **self.op_kwargs)
  File "/opt/airflow/dags/first_dag.py", line 21, in respond
    df = pd.read_csv("20181101_d7_1000_1030.csv", delimiter=";")
  File "/home/airflow/.local/lib/python3.7/site-packages/pandas/util/_decorators.py", line 311, in wrapper
    return func(*args, **kwargs)
  File "/home/airflow/.local/lib/python3.7/site-packages/pandas/io/parsers/readers.py", line 586, in read_csv
    return _read(filepath_or_buffer, kwds)
  File "/home/airflow/.local/lib/python3.7/site-packages/pandas/io/parsers/readers.py", line 482, in _read
    parser = TextFileReader(filepath_or_buffer, **kwds)
  File "/home/airflow/.local/lib/python3.7/site-packages/pandas/io/parsers/readers.py", line 811, in __init__
    self._engine = self._make_engine(self.engine)
  File "/home/airflow/.local/lib/python3.7/site-packages/pandas/io/parsers/readers.py", line 1040, in _make_engine
    return mapping[engine](self.f, **self.options)  # type: ignore[call-arg]
  File "/home/airflow/.local/lib/python3.7/site-packages/pandas/io/parsers/c_parser_wrapper.py", line 51, in __init__
    self._open_handles(src, kwds)
  File "/home/airflow/.local/lib/python3.7/site-packages/pandas/io/parsers/base_parser.py", line 229, in _open_handles
    errors=kwds.get("encoding_errors", "strict"),
  File "/home/airflow/.local/lib/python3.7/site-packages/pandas/io/common.py", line 707, in get_handle
    newline="",
FileNotFoundError: [Errno 2] No such file or directory: '20181101_d7_1000_1030.csv'
[2022-07-19 09:29:35,265] {taskinstance.py:1400} INFO - Marking task as FAILED. dag_id=simple_dag, task_id=respond, execution_date=20220719T092925, start_date=20220719T092935, end_date=20220719T092935
[2022-07-19 09:29:35,277] {standard_task_runner.py:97} ERROR - Failed to execute job 217 for task respond ([Errno 2] No such file or directory: '20181101_d7_1000_1030.csv'; 4600)
[2022-07-19 09:29:35,322] {local_task_job.py:156} INFO - Task exited with return code 1
[2022-07-19 09:29:35,379] {local_task_job.py:273} INFO - 0 downstream tasks scheduled from follow-on schedule check
