[2022-07-19 08:27:17,044] {taskinstance.py:1159} INFO - Dependencies all met for <TaskInstance: simple_dag.greet manual__2022-07-19T08:27:14.571582+00:00 [queued]>
[2022-07-19 08:27:17,061] {taskinstance.py:1159} INFO - Dependencies all met for <TaskInstance: simple_dag.greet manual__2022-07-19T08:27:14.571582+00:00 [queued]>
[2022-07-19 08:27:17,061] {taskinstance.py:1356} INFO - 
--------------------------------------------------------------------------------
[2022-07-19 08:27:17,062] {taskinstance.py:1357} INFO - Starting attempt 1 of 1
[2022-07-19 08:27:17,062] {taskinstance.py:1358} INFO - 
--------------------------------------------------------------------------------
[2022-07-19 08:27:17,086] {taskinstance.py:1377} INFO - Executing <Task(PythonOperator): greet> on 2022-07-19 08:27:14.571582+00:00
[2022-07-19 08:27:17,092] {standard_task_runner.py:52} INFO - Started process 1151 to run task
[2022-07-19 08:27:17,096] {standard_task_runner.py:79} INFO - Running: ['***', 'tasks', 'run', 'simple_dag', 'greet', 'manual__2022-07-19T08:27:14.571582+00:00', '--job-id', '35', '--raw', '--subdir', 'DAGS_FOLDER/first_dag.py', '--cfg-path', '/tmp/tmpqtlw2j3k', '--error-file', '/tmp/tmp3c7rugcy']
[2022-07-19 08:27:17,096] {standard_task_runner.py:80} INFO - Job 35: Subtask greet
[2022-07-19 08:27:17,180] {task_command.py:370} INFO - Running <TaskInstance: simple_dag.greet manual__2022-07-19T08:27:14.571582+00:00 [running]> on host 02ffb48252da
[2022-07-19 08:27:17,273] {taskinstance.py:1571} INFO - Exporting the following env vars:
AIRFLOW_CTX_DAG_OWNER=***
AIRFLOW_CTX_DAG_ID=simple_dag
AIRFLOW_CTX_TASK_ID=greet
AIRFLOW_CTX_EXECUTION_DATE=2022-07-19T08:27:14.571582+00:00
AIRFLOW_CTX_TRY_NUMBER=1
AIRFLOW_CTX_DAG_RUN_ID=manual__2022-07-19T08:27:14.571582+00:00
[2022-07-19 08:27:17,275] {logging_mixin.py:115} INFO - Writing in file
[2022-07-19 08:27:17,275] {taskinstance.py:1889} ERROR - Task failed with exception
Traceback (most recent call last):
  File "/home/airflow/.local/lib/python3.7/site-packages/airflow/operators/python.py", line 171, in execute
    return_value = self.execute_callable()
  File "/home/airflow/.local/lib/python3.7/site-packages/airflow/operators/python.py", line 189, in execute_callable
    return self.python_callable(*self.op_args, **self.op_kwargs)
  File "/opt/airflow/dags/first_dag.py", line 12, in greet
    with open("/opt/airflow/dags", "a+", encoding="utf8") as f:
IsADirectoryError: [Errno 21] Is a directory: '/opt/airflow/dags'
[2022-07-19 08:27:17,288] {taskinstance.py:1400} INFO - Marking task as FAILED. dag_id=simple_dag, task_id=greet, execution_date=20220719T082714, start_date=20220719T082717, end_date=20220719T082717
[2022-07-19 08:27:17,301] {standard_task_runner.py:97} ERROR - Failed to execute job 35 for task greet ([Errno 21] Is a directory: '/opt/airflow/dags'; 1151)
[2022-07-19 08:27:17,309] {local_task_job.py:156} INFO - Task exited with return code 1
[2022-07-19 08:27:17,351] {local_task_job.py:273} INFO - 0 downstream tasks scheduled from follow-on schedule check
