[2022-07-19 08:22:35,423] {taskinstance.py:1159} INFO - Dependencies all met for <TaskInstance: simple_dag.greet manual__2022-07-19T08:22:32.729866+00:00 [queued]>
[2022-07-19 08:22:35,467] {taskinstance.py:1159} INFO - Dependencies all met for <TaskInstance: simple_dag.greet manual__2022-07-19T08:22:32.729866+00:00 [queued]>
[2022-07-19 08:22:35,468] {taskinstance.py:1356} INFO - 
--------------------------------------------------------------------------------
[2022-07-19 08:22:35,470] {taskinstance.py:1357} INFO - Starting attempt 1 of 1
[2022-07-19 08:22:35,474] {taskinstance.py:1358} INFO - 
--------------------------------------------------------------------------------
[2022-07-19 08:22:35,544] {taskinstance.py:1377} INFO - Executing <Task(PythonOperator): greet> on 2022-07-19 08:22:32.729866+00:00
[2022-07-19 08:22:35,569] {standard_task_runner.py:79} INFO - Running: ['***', 'tasks', 'run', 'simple_dag', 'greet', 'manual__2022-07-19T08:22:32.729866+00:00', '--job-id', '33', '--raw', '--subdir', 'DAGS_FOLDER/first_dag.py', '--cfg-path', '/tmp/tmplqy7rgze', '--error-file', '/tmp/tmp_4zjvpa8']
[2022-07-19 08:22:35,562] {standard_task_runner.py:52} INFO - Started process 923 to run task
[2022-07-19 08:22:35,570] {standard_task_runner.py:80} INFO - Job 33: Subtask greet
[2022-07-19 08:22:35,787] {task_command.py:370} INFO - Running <TaskInstance: simple_dag.greet manual__2022-07-19T08:22:32.729866+00:00 [running]> on host 02ffb48252da
[2022-07-19 08:22:35,990] {taskinstance.py:1571} INFO - Exporting the following env vars:
AIRFLOW_CTX_DAG_OWNER=***
AIRFLOW_CTX_DAG_ID=simple_dag
AIRFLOW_CTX_TASK_ID=greet
AIRFLOW_CTX_EXECUTION_DATE=2022-07-19T08:22:32.729866+00:00
AIRFLOW_CTX_TRY_NUMBER=1
AIRFLOW_CTX_DAG_RUN_ID=manual__2022-07-19T08:22:32.729866+00:00
[2022-07-19 08:22:35,992] {logging_mixin.py:115} INFO - Writing in file
[2022-07-19 08:22:35,993] {taskinstance.py:1889} ERROR - Task failed with exception
Traceback (most recent call last):
  File "/home/airflow/.local/lib/python3.7/site-packages/airflow/operators/python.py", line 171, in execute
    return_value = self.execute_callable()
  File "/home/airflow/.local/lib/python3.7/site-packages/airflow/operators/python.py", line 189, in execute_callable
    return self.python_callable(*self.op_args, **self.op_kwargs)
  File "/opt/airflow/dags/first_dag.py", line 12, in greet
    with open(Path().cwd(), "a+", encoding="utf8") as f:
IsADirectoryError: [Errno 21] Is a directory: '/opt/airflow'
[2022-07-19 08:22:36,012] {taskinstance.py:1400} INFO - Marking task as FAILED. dag_id=simple_dag, task_id=greet, execution_date=20220719T082232, start_date=20220719T082235, end_date=20220719T082236
[2022-07-19 08:22:36,041] {standard_task_runner.py:97} ERROR - Failed to execute job 33 for task greet ([Errno 21] Is a directory: '/opt/airflow'; 923)
[2022-07-19 08:22:36,076] {local_task_job.py:156} INFO - Task exited with return code 1
[2022-07-19 08:22:36,244] {local_task_job.py:273} INFO - 0 downstream tasks scheduled from follow-on schedule check
